Workbook

Sheet Mode d'emploi
B2: COURRIER D'AUGMENTATION TARIFAIRE — PUBLIPOSTAGE
B3: Compta · Paye · Juridique · Plateforme agréée
B5: 1. Onglet « Paramètres »
B6: Renseignez les coordonnées du cabinet, le signataire, la date d'effet, les taux d'augmentation par mission et, si besoin, adaptez les textes du courrier. Les balises {cabinet}, {societe}, {date_effet}, {hausse} et {civilite} sont remplacées automatiquement.
B8: 2. Onglet « Clients »
B9: Une ligne par client. Colonnes bleues = saisie ; colonnes vertes = calcul automatique (ne pas modifier). Saisissez les honoraires ANNUELS HT actuels par mission (0 ou vide si la mission n'est pas souscrite : elle n'apparaîtra pas dans le courrier). « Taux perso » remplace les taux par défaut pour ce client. Les 3 lignes d'exemple (C001 à C003) sont à remplacer par vos clients.
B11: 3. Onglet « Courrier » — un client à la fois
B12: Choisissez le code client dans la cellule jaune I3 : le courrier se remplit tout seul. Puis Fichier > Exporter > Créer un PDF (ou Enregistrer sous > PDF) pour l'envoi par e-mail, ou Fichier > Imprimer pour l'envoi postal. La mise en page A4 est déjà réglée (1 page, adresse du destinataire positionnée pour une enveloppe à fenêtre à droite).
B14: 4. IMPRESSION EN MASSE — onglet « Impression en masse » (sans macro)
B15: Cet onglet contient tous les courriers les uns à la suite des autres, un par page A4. Y figurent les clients dont « À envoyer » = Oui (et, par défaut, dont le mode d'envoi est Courrier ou Les deux — réglable dans Paramètres > Impression en masse). Cliquez sur l'onglet puis Fichier > Imprimer : toutes les lettres sortent d'un coup, recto simple. Pour un PDF unique : Fichier > Exporter > PDF avec cet onglet actif. La colonne Z de l'onglet Clients indique le numéro de page de chaque client. Capacité : 300 courriers.
B17: 5. Un PDF séparé par client — macro « Macro PDF » (facultatif)
B18: Enregistrez le fichier au format .xlsm (Classeur Excel prenant en charge les macros), ouvrez l'éditeur VBA (Alt + F11), Insertion > Module, collez le code de l'onglet « Macro PDF » (ou importez le fichier Module_Courriers.bas). Lancez ensuite (Alt + F8) : • ExporterTousLesPDF : un PDF par client dont « À envoyer » = Oui, dans le dossier Courriers_PDF • ExporterUnSeulPDF : un seul PDF regroupant tous les courriers (pratique pour un envoi en masse) • ImprimerCourriersPostaux : impression des clients « À envoyer » = Oui et mode Courrier / Les deux
... B24: Texte bleu sur fond jaune = cellule à renseigner · Fond gris = formule · Colonnes grises à droite du courrier (J à O) = calculs internes, non imprimés.

Sheet Paramètres
A1: PARAMÈTRES DU COURRIER
A2: Cellules sur fond jaune / texte bleu = à personnaliser. Balises utilisables dans les textes : {cabinet} {societe} {date_effet} {hausse}
A5: Coordonnées du cabinet
A6: Nom du cabinet | B6: ALTHO EXPERTISE
A7: Adresse | B7: 141 rue Charles de Gaulle
A8: Code postal et ville | B8: 95130 LE PLESSIS-BOUCHARD
A9: Ville (lieu de signature) | B9: Le Plessis-Bouchard
A10: Téléphone / e-mail | B10: Tél. 01 34 14 53 45 · altho@altho-experts.com · altho-experts.com
A11: Mentions légales (pied de page) | B11: ALTHO EXPERTISE · SAS au capital de 10 000 € · RCS Pontoise 919 706 325 · TVA FR62919706325 · Société d'expertise comptable inscrite au Tableau de l'Ordre des experts-comptables de Paris Île-de-France
A12: Nom du signataire | B12: Prénom NOM
A13: Fonction du signataire | B13: Expert-comptable associé
A15: Dates
A16: Date du courrier | B16: =TODAY() -> 46287
A17: Date d'effet des nouveaux tarifs | B17: =DATE(YEAR(Date_Courrier)+1,1,1) -> 46388
A19: Taux d'augmentation par défaut (par mission)
A20: Comptabilité | B20: 0.035
A21: Paye / social | B21: 0.04
A22: Juridique | B22: 0.03
A23: Plateforme agréée (facturation électronique) | B23: 0
A24: Arrondi des nouveaux honoraires (en €) | B24: 1
A25: Nombre d'échéances par an (mensualisation) | B25: 12
A26: Taux de TVA | B26: 0.2
A28: Impression en masse
A29: Clients à inclure | B29: Courrier postal uniquement
A31: Libellés des missions (tels qu'imprimés dans le courrier)
A32: Mission 1 | B32: Mission comptable (tenue, révision, bilan, liasse fiscale)
A33: Mission 2 | B33: Mission sociale (bulletins de paie, DSN, déclarations sociales)
A34: Mission 3 | B34: Mission juridique (approbation des comptes, secrétariat juridique)
A35: Mission 4 | B35: Plateforme agréée – facturation électronique
A37: Textes du courrier (modifiables — laissez vide pour supprimer un paragraphe)
A38: Objet | B38: Objet : révision de nos honoraires au {date_effet}
A39: Paragraphe 1 | B39: Nous tenons tout d'abord à vous remercier pour la confiance que vous accordez à {cabinet}. Comme chaque année, et conformément aux dispositions de votre lettre de mission, nous procédons à la révision de nos honoraires.
A40: Paragraphe 2 | B40: Cette révision, que nous avons souhaitée mesurée, tient compte de l'évolution de nos charges (rémunération et formation continue de nos collaborateurs, logiciels, sécurité informatique) ainsi que du renforcement constant des obligations comptables, fiscales, sociales et juridiques qui s'imposent à votre entreprise.
A41: Paragraphe 3 (facturation électronique) | B41: L'année à venir est également marquée par la généralisation de la facturation électronique : depuis le 1er septembre 2026, toutes les entreprises doivent être en mesure de recevoir leurs factures électroniques via une plateforme agréée, et l'obligation d'émission s'étendra aux PME et micro-entreprises au 1er septembre 2027. Notre cabinet vous accompagne dans cette transition grâce à une solution de plateforme agréée directement intégrée à votre dossier.
A42: Paragraphe 4 (avant le tableau) | B42: À compter du {date_effet}, vos honoraires annuels hors taxes évolueront ainsi (évolution globale : {hausse}) :
A43: Paragraphe 5 (après le tableau) | B43: Les autres conditions de votre lettre de mission demeurent inchangées. Les nouveaux montants seront appliqués automatiquement sur vos prochaines factures et échéances de prélèvement.
A44: Paragraphe 6 | B44: Votre interlocuteur habituel reste à votre entière disposition pour répondre à vos questions et faire le point sur l'évolution de vos besoins.
A45: Formule de politesse | B45: Nous vous prions d'agréer, {civilite}, l'expression de nos salutations distinguées.
A48: Mois (usage interne) | B48: janvier
B49: février
...

Sheet Clients
A1: Code client | B1: Civilité | C1: Prénom | D1: Nom | E1: Société | F1: Adresse 1 | G1: Adresse 2 | H1: Code postal | I1: Ville | J1: Email | K1: Compta actuel HT | L1: Paye actuel HT | M1: Juridique actuel HT | N1: PA actuel HT | O1: Taux perso (optionnel) | P1: Compta nouveau HT | Q1: Paye nouveau HT | R1: Juridique nouveau HT | S1: PA nouveau HT | T1: Total actuel HT | U1: Total nouveau HT | V1: Écart HT | W1: Écart % | X1: À envoyer | Y1: Mode d'envoi | Z1: N° impression en masse
A2: C001 | B2: M. | C2: Pierre | D2: DURAND | E2: SARL DURAND BÂTIMENT | F2: 5 avenue des Tilleuls | H2: 69100 | I2: Villeurbanne | J2: p.durand@exemple.fr | K2: 3600 | L2: 1800 | M2: 600 | N2: 240 | P2: =IF(OR($A2="",N(K2)=0),0,CEILING(K2*(1+IF($O2="",Taux_Compta,$O2))-0.005,Pas_Arrondi)) -> 3726 | Q2: =IF(OR($A2="",N(L2)=0),0,CEILING(L2*(1+IF($O2="",Taux_Paye,$O2))-0.005,Pas_Arrondi)) -> 1872 | R2: =IF(OR($A2="",N(M2)=0),0,CEILING(M2*(1+IF($O2="",Taux_Jur,$O2))-0.005,Pas_Arrondi)) -> 618 | S2: =IF(OR($A2="",N(N2)=0),0,CEILING(N2*(1+IF($O2="",Taux_PA,$O2))-0.005,Pas_Arrondi)) -> 240 | T2: =IF($A2="","",SUM(K2:N2)) -> 6240 | U2: =IF($A2="","",SUM(P2:S2)) -> 6456 | V2: =IF($A2="","",U2-T2) -> 216 | W2: =IF(OR($A2="",N(T2)=0),"",V2/T2) -> 0.034615385 | X2: Oui | Y2: Courrier | Z2: =IF(AND($A2<>"",$X2="Oui",OR(Filtre_Masse="Tous les clients à envoyer",$Y2<>"Email")),MAX(Z$1:Z1)+1,"") -> 1
A3: C002 | B3: Mme | C3: Sophie | D3: LEROY | E3: SAS LEROY CONSEIL | F3: Parc d'activités du Moulin | G3: Bât. B – 3 allée Verte | H3: 38000 | I3: Grenoble | J3: s.leroy@exemple.fr | K3: 5400 | L3: 0 | M3: 900 | N3: 0 | O3: 0.025 | P3: =IF(OR($A3="",N(K3)=0),0,CEILING(K3*(1+IF($O3="",Taux_Compta,$O3))-0.005,Pas_Arrondi)) -> 5535 | Q3: =IF(OR($A3="",N(L3)=0),0,CEILING(L3*(1+IF($O3="",Taux_Paye,$O3))-0.005,Pas_Arrondi)) -> 0 | R3: =IF(OR($A3="",N(M3)=0),0,CEILING(M3*(1+IF($O3="",Taux_Jur,$O3))-0.005,Pas_Arrondi)) -> 923 | S3: =IF(OR($A3="",N(N3)=0),0,CEILING(N3*(1+IF($O3="",Taux_PA,$O3))-0.005,Pas_Arrondi)) -> 0 | T3: =IF($A3="","",SUM(K3:N3)) -> 6300 | U3: =IF($A3="","",SUM(P3:S3)) -> 6458 | V3: =IF($A3="","",U3-T3) -> 158 | W3: =IF(OR($A3="",N(T3)=0),"",V3/T3) -> 0.025079365 | X3: Oui | Y3: Email | Z3: =IF(AND($A3<>"",$X3="Oui",OR(Filtre_Masse="Tous les clients à envoyer",$Y3<>"Email")),MAX(Z$1:Z2)+1,"")
A4: C003 | E4: EURL LES JARDINS DE CLAIRE | F4: 18 chemin des Vignes | H4: 69400 | I4: Villefranche-sur-Saône | J4: contact@jardins-claire.fr | K4: 2400 | L4: 1200 | M4: 0 | N4: 180 | P4: =IF(OR($A4="",N(K4)=0),0,CEILING(K4*(1+IF($O4="",Taux_Compta,$O4))-0.005,Pas_Arrondi)) -> 2484 | Q4: =IF(OR($A4="",N(L4)=0),0,CEILING(L4*(1+IF($O4="",Taux_Paye,$O4))-0.005,Pas_Arrondi)) -> 1248 | R4: =IF(OR($A4="",N(M4)=0),0,CEILING(M4*(1+IF($O4="",Taux_Jur,$O4))-0.005,Pas_Arrondi)) -> 0 | S4: =IF(OR($A4="",N(N4)=0),0,CEILING(N4*(1+IF($O4="",Taux_PA,$O4))-0.005,Pas_Arrondi)) -> 180 | T4: =IF($A4="","",SUM(K4:N4)) -> 3780 | U4: =IF($A4="","",SUM(P4:S4)) -> 3912 | V4: =IF($A4="","",U4-T4) -> 132 | W4: =IF(OR($A4="",N(T4)=0),"",V4/T4) -> 0.034920635 | X4: Oui | Y4: Les deux | Z4: =IF(AND($A4<>"",$X4="Oui",OR(Filtre_Masse="Tous les clients à envoyer",$Y4<>"Email")),MAX(Z$1:Z3)+1,"") -> 2
P5: =IF(OR($A5="",N(K5)=0),0,CEILING(K5*(1+IF($O5="",Taux_Compta,$O5))-0.005,Pas_Arrondi)) -> 0 | Q5: =IF(OR($A5="",N(L5)=0),0,CEILING(L5*(1+IF($O5="",Taux_Paye,$O5))-0.005,Pas_Arrondi)) -> 0 | R5: =IF(OR($A5="",N(M5)=0),0,CEILING(M5*(1+IF($O5="",Taux_Jur,$O5))-0.005,Pas_Arrondi)) -> 0 | S5: =IF(OR($A5="",N(N5)=0),0,CEILING(N5*(1+IF($O5="",Taux_PA,$O5))-0.005,Pas_Arrondi)) -> 0 | T5: =IF($A5="","",SUM(K5:N5)) | U5: =IF($A5="","",SUM(P5:S5)) | V5: =IF($A5="","",U5-T5) | W5: =IF(OR($A5="",N(T5)=0),"",V5/T5) | Z5: =IF(AND($A5<>"",$X5="Oui",OR(Filtre_Masse="Tous les clients à envoyer",$Y5<>"Email")),MAX(Z$1:Z4)+1,"")
P6: =IF(OR($A6="",N(K6)=0),0,CEILING(K6*(1+IF($O6="",Taux_Compta,$O6))-0.005,Pas_Arrondi)) -> 0 | Q6: =IF(OR($A6="",N(L6)=0),0,CEILING(L6*(1+IF($O6="",Taux_Paye,$O6))-0.005,Pas_Arrondi)) -> 0 | R6: =IF(OR($A6="",N(M6)=0),0,CEILING(M6*(1+IF($O6="",Taux_Jur,$O6))-0.005,Pas_Arrondi)) -> 0 | S6: =IF(OR($A6="",N(N6)=0),0,CEILING(N6*(1+IF($O6="",Taux_PA,$O6))-0.005,Pas_Arrondi)) -> 0 | T6: =IF($A6="","",SUM(K6:N6)) | U6: =IF($A6="","",SUM(P6:S6)) | V6: =IF($A6="","",U6-T6) | W6: =IF(OR($A6="",N(T6)=0),"",V6/T6) | Z6: =IF(AND($A6<>"",$X6="Oui",OR(Filtre_Masse="Tous les clients à envoyer",$Y6<>"Email")),MAX(Z$1:Z5)+1,"")
P7: =IF(OR($A7="",N(K7)=0),0,CEILING(K7*(1+IF($O7="",Taux_Compta,$O7))-0.005,Pas_Arrondi)) -> 0 | Q7: =IF(OR($A7="",N(L7)=0),0,CEILING(L7*(1+IF($O7="",Taux_Paye,$O7))-0.005,Pas_Arrondi)) -> 0 | R7: =IF(OR($A7="",N(M7)=0),0,CEILING(M7*(1+IF($O7="",Taux_Jur,$O7))-0.005,Pas_Arrondi)) -> 0 | S7: =IF(OR($A7="",N(N7)=0),0,CEILING(N7*(1+IF($O7="",Taux_PA,$O7))-0.005,Pas_Arrondi)) -> 0 | T7: =IF($A7="","",SUM(K7:N7)) | U7: =IF($A7="","",SUM(P7:S7)) | V7: =IF($A7="","",U7-T7) | W7: =IF(OR($A7="",N(T7)=0),"",V7/T7) | Z7: =IF(AND($A7<>"",$X7="Oui",OR(Filtre_Masse="Tous les clients à envoyer",$Y7<>"Email")),MAX(Z$1:Z6)+1,"")
P8: =IF(OR($A8="",N(K8)=0),0,CEILING(K8*(1+IF($O8="",Taux_Compta,$O8))-0.005,Pas_Arrondi)) -> 0 | Q8: =IF(OR($A8="",N(L8)=0),0,CEILING(L8*(1+IF($O8="",Taux_Paye,$O8))-0.005,Pas_Arrondi)) -> 0 | R8: =IF(OR($A8="",N(M8)=0),0,CEILING(M8*(1+IF($O8="",Taux_Jur,$O8))-0.005,Pas_Arrondi)) -> 0 | S8: =IF(OR($A8="",N(N8)=0),0,CEILING(N8*(1+IF($O8="",Taux_PA,$O8))-0.005,Pas_Arrondi)) -> 0 | T8: =IF($A8="","",SUM(K8:N8)) | U8: =IF($A8="","",SUM(P8:S8)) | V8: =IF($A8="","",U8-T8) | W8: =IF(OR($A8="",N(T8)=0),"",V8/T8) | Z8: =IF(AND($A8<>"",$X8="Oui",OR(Filtre_Masse="Tous les clients à envoyer",$Y8<>"Email")),MAX(Z$1:Z7)+1,"")
P9: =IF(OR($A9="",N(K9)=0),0,CEILING(K9*(1+IF($O9="",Taux_Compta,$O9))-0.005,Pas_Arrondi)) -> 0 | Q9: =IF(OR($A9="",N(L9)=0),0,CEILING(L9*(1+IF($O9="",Taux_Paye,$O9))-0.005,Pas_Arrondi)) -> 0 | R9: =IF(OR($A9="",N(M9)=0),0,CEILING(M9*(1+IF($O9="",Taux_Jur,$O9))-0.005,Pas_Arrondi)) -> 0 | S9: =IF(OR($A9="",N(N9)=0),0,CEILING(N9*(1+IF($O9="",Taux_PA,$O9))-0.005,Pas_Arrondi)) -> 0 | T9: =IF($A9="","",SUM(K9:N9)) | U9: =IF($A9="","",SUM(P9:S9)) | V9: =IF($A9="","",U9-T9) | W9: =IF(OR($A9="",N(T9)=0),"",V9/T9) | Z9: =IF(AND($A9<>"",$X9="Oui",OR(Filtre_Masse="Tous les clients à envoyer",$Y9<>"Email")),MAX(Z$1:Z8)+1,"")
P10: =IF(OR($A10="",N(K10)=0),0,CEILING(K10*(1+IF($O10="",Taux_Compta,$O10))-0.005,Pas_Arrondi)) -> 0 | Q10: =IF(OR($A10="",N(L10)=0),0,CEILING(L10*(1+IF($O10="",Taux_Paye,$O10))-0.005,Pas_Arrondi)) -> 0 | R10: =IF(OR($A10="",N(M10)=0),0,CEILING(M10*(1+IF($O10="",Taux_Jur,$O10))-0.005,Pas_Arrondi)) -> 0 | S10: =IF(OR($A10="",N(N10)=0),0,CEILING(N10*(1+IF($O10="",Taux_PA,$O10))-0.005,Pas_Arrondi)) -> 0 | T10: =IF($A10="","",SUM(K10:N10)) | U10: =IF($A10="","",SUM(P10:S10)) | V10: =IF($A10="","",U10-T10) | W10: =IF(OR($A10="",N(T10)=0),"",V10/T10) | Z10: =IF(AND($A10<>"",$X10="Oui",OR(Filtre_Masse="Tous les clients à envoyer",$Y10<>"Email")),MAX(Z$1:Z9)+1,"")
P11: =IF(OR($A11="",N(K11)=0),0,CEILING(K11*(1+IF($O11="",Taux_Compta,$O11))-0.005,Pas_Arrondi)) -> 0 | Q11: =IF(OR($A11="",N(L11)=0),0,CEILING(L11*(1+IF($O11="",Taux_Paye,$O11))-0.005,Pas_Arrondi)) -> 0 | R11: =IF(OR($A11="",N(M11)=0),0,CEILING(M11*(1+IF($O11="",Taux_Jur,$O11))-0.005,Pas_Arrondi)) -> 0 | S11: =IF(OR($A11="",N(N11)=0),0,CEILING(N11*(1+IF($O11="",Taux_PA,$O11))-0.005,Pas_Arrondi)) -> 0 | T11: =IF($A11="","",SUM(K11:N11)) | U11: =IF($A11="","",SUM(P11:S11)) | V11: =IF($A11="","",U11-T11) | W11: =IF(OR($A11="",N(T11)=0),"",V11/T11) | Z11: =IF(AND($A11<>"",$X11="Oui",OR(Filtre_Masse="Tous les clients à envoyer",$Y11<>"Email")),MAX(Z$1:Z10)+1,"")
P12: =IF(OR($A12="",N(K12)=0),0,CEILING(K12*(1+IF($O12="",Taux_Compta,$O12))-0.005,Pas_Arrondi)) -> 0 | Q12: =IF(OR($A12="",N(L12)=0),0,CEILING(L12*(1+IF($O12="",Taux_Paye,$O12))-0.005,Pas_Arrondi)) -> 0 | R12: =IF(OR($A12="",N(M12)=0),0,CEILING(M12*(1+IF($O12="",Taux_Jur,$O12))-0.005,Pas_Arrondi)) -> 0 | S12: =IF(OR($A12="",N(N12)=0),0,CEILING(N12*(1+IF($O12="",Taux_PA,$O12))-0.005,Pas_Arrondi)) -> 0 | T12: =IF($A12="","",SUM(K12:N12)) | U12: =IF($A12="","",SUM(P12:S12)) | V12: =IF($A12="","",U12-T12) | W12: =IF(OR($A12="",N(T12)=0),"",V12/T12) | Z12: =IF(AND($A12<>"",$X12="Oui",OR(Filtre_Masse="Tous les clients à envoyer",$Y12<>"Email")),MAX(Z$1:Z11)+1,"")
P13: =IF(OR($A13="",N(K13)=0),0,CEILING(K13*(1+IF($O13="",Taux_Compta,$O13))-0.005,Pas_Arrondi)) -> 0 | Q13: =IF(OR($A13="",N(L13)=0),0,CEILING(L13*(1+IF($O13="",Taux_Paye,$O13))-0.005,Pas_Arrondi)) -> 0 | R13: =IF(OR($A13="",N(M13)=0),0,CEILING(M13*(1+IF($O13="",Taux_Jur,$O13))-0.005,Pas_Arrondi)) -> 0 | S13: =IF(OR($A13="",N(N13)=0),0,CEILING(N13*(1+IF($O13="",Taux_PA,$O13))-0.005,Pas_Arrondi)) -> 0 | T13: =IF($A13="","",SUM(K13:N13)) | U13: =IF($A13="","",SUM(P13:S13)) | V13: =IF($A13="","",U13-T13) | W13: =IF(OR($A13="",N(T13)=0),"",V13/T13) | Z13: =IF(AND($A13<>"",$X13="Oui",OR(Filtre_Masse="Tous les clients à envoyer",$Y13<>"Email")),MAX(Z$1:Z12)+1,"")
P14: =IF(OR($A14="",N(K14)=0),0,CEILING(K14*(1+IF($O14="",Taux_Compta,$O14))-0.005,Pas_Arrondi)) -> 0 | Q14: =IF(OR($A14="",N(L14)=0),0,CEILING(L14*(1+IF($O14="",Taux_Paye,$O14))-0.005,Pas_Arrondi)) -> 0 | R14: =IF(OR($A14="",N(M14)=0),0,CEILING(M14*(1+IF($O14="",Taux_Jur,$O14))-0.005,Pas_Arrondi)) -> 0 | S14: =IF(OR($A14="",N(N14)=0),0,CEILING(N14*(1+IF($O14="",Taux_PA,$O14))-0.005,Pas_Arrondi)) -> 0 | T14: =IF($A14="","",SUM(K14:N14)) | U14: =IF($A14="","",SUM(P14:S14)) | V14: =IF($A14="","",U14-T14) | W14: =IF(OR($A14="",N(T14)=0),"",V14/T14) | Z14: =IF(AND($A14<>"",$X14="Oui",OR(Filtre_Masse="Tous les clients à envoyer",$Y14<>"Email")),MAX(Z$1:Z13)+1,"")
P15: =IF(OR($A15="",N(K15)=0),0,CEILING(K15*(1+IF($O15="",Taux_Compta,$O15))-0.005,Pas_Arrondi)) -> 0 | Q15: =IF(OR($A15="",N(L15)=0),0,CEILING(L15*(1+IF($O15="",Taux_Paye,$O15))-0.005,Pas_Arrondi)) -> 0 | R15: =IF(OR($A15="",N(M15)=0),0,CEILING(M15*(1+IF($O15="",Taux_Jur,$O15))-0.005,Pas_Arrondi)) -> 0 | S15: =IF(OR($A15="",N(N15)=0),0,CEILING(N15*(1+IF($O15="",Taux_PA,$O15))-0.005,Pas_Arrondi)) -> 0 | T15: =IF($A15="","",SUM(K15:N15)) | U15: =IF($A15="","",SUM(P15:S15)) | V15: =IF($A15="","",U15-T15) | W15: =IF(OR($A15="",N(T15)=0),"",V15/T15) | Z15: =IF(AND($A15<>"",$X15="Oui",OR(Filtre_Masse="Tous les clients à envoyer",$Y15<>"Email")),MAX(Z$1:Z14)+1,"")
P16: =IF(OR($A16="",N(K16)=0),0,CEILING(K16*(1+IF($O16="",Taux_Compta,$O16))-0.005,Pas_Arrondi)) -> 0 | Q16: =IF(OR($A16="",N(L16)=0),0,CEILING(L16*(1+IF($O16="",Taux_Paye,$O16))-0.005,Pas_Arrondi)) -> 0 | R16: =IF(OR($A16="",N(M16)=0),0,CEILING(M16*(1+IF($O16="",Taux_Jur,$O16))-0.005,Pas_Arrondi)) -> 0 | S16: =IF(OR($A16="",N(N16)=0),0,CEILING(N16*(1+IF($O16="",Taux_PA,$O16))-0.005,Pas_Arrondi)) -> 0 | T16: =IF($A16="","",SUM(K16:N16)) | U16: =IF($A16="","",SUM(P16:S16)) | V16: =IF($A16="","",U16-T16) | W16: =IF(OR($A16="",N(T16)=0),"",V16/T16) | Z16: =IF(AND($A16<>"",$X16="Oui",OR(Filtre_Masse="Tous les clients à envoyer",$Y16<>"Email")),MAX(Z$1:Z15)+1,"")
... P501: =IF(OR($A501="",N(K501)=0),0,CEILING(K501*(1+IF($O501="",Taux_Compta,$O501))-0.005,Pas_Arrondi)) -> 0 | Q501: =IF(OR($A501="",N(L501)=0),0,CEILING(L501*(1+IF($O501="",Taux_Paye,$O501))-0.005,Pas_Arrondi)) -> 0 | R501: =IF(OR($A501="",N(M501)=0),0,CEILING(M501*(1+IF($O501="",Taux_Jur,$O501))-0.005,Pas_Arrondi)) -> 0 | S501: =IF(OR($A501="",N(N501)=0),0,CEILING(N501*(1+IF($O501="",Taux_PA,$O501))-0.005,Pas_Arrondi)) -> 0 | T501: =IF($A501="","",SUM(K501:N501)) | U501: =IF($A501="","",SUM(P501:S501)) | V501: =IF($A501="","",U501-T501) | W501: =IF(OR($A501="",N(T501)=0),"",V501/T501) | Z501: =IF(AND($A501<>"",$X501="Oui",OR(Filtre_Masse="Tous les clients à envoyer",$Y501<>"Email")),MAX(Z$1:Z500)+1,"")

Sheet Courrier
J1: Ligne client | K1: =IFERROR(MATCH(Client_Selectionne,Codes_Clients,0),0) -> 1
B2: =Cab_Nom -> ALTHO EXPERTISE | E2: ="Réf. client : "&Client_Selectionne -> Réf. client : C001 | I2: CLIENT À ÉDITER ▼ | J2: Civilité longue | K2: =IF(IF($K$1=0,"",INDEX(Clients!$B$2:$B$501,$K$1)&"")="Mme","Madame",IF(IF($K$1=0,"",INDEX(Clients!$B$2:$B$501,$K$1)&"")="M.","Monsieur","Madame, Monsieur")) -> Monsieur
B3: =Cab_Adr1 -> 141 rue Charles de Gaulle | I3: C001 | J3: Date effet texte | K3: =DAY(Date_Effet)&IF(DAY(Date_Effet)=1,"er","")&" "&INDEX(Liste_Mois,MONTH(Date_Effet))&" "&YEAR(Date_Effet) -> 1er janvier 2027
B4: =Cab_CPVille -> 95130 LE PLESSIS-BOUCHARD | I4: =IFERROR(INDEX(Clients!$E$2:$E$501,MATCH(Client_Selectionne,Codes_Clients,0)),"Code introuvable") -> SARL DURAND BÂTIMENT | J4: Hausse globale | K4: =IF(SUM($K$28:$K$31)=0,"",FIXED((SUM($L$28:$L$31)/SUM($K$28:$K$31)-1)*100,1)&" %") -> 3.5 %
B5: =Cab_Contact -> Tél. 01 34 14 53 45 · altho@altho-experts.com · altho-experts.com
I6: Choisissez le code client dans la liste, puis : Fichier > Exporter > PDF (1 client) ou Fichier > Imprimer. Pour tous les clients : onglet « Impression en masse ».
D10: =IF($K$1=0,"",INDEX(Clients!$E$2:$E$501,$K$1)&"") -> SARL DURAND BÂTIMENT
D11: =IF(IF($K$1=0,"",INDEX(Clients!$D$2:$D$501,$K$1)&"")="","","À l'attention de "&TRIM(IF($K$1=0,"",INDEX(Clients!$B$2:$B$501,$K$1)&"")&" "&IF($K$1=0,"",INDEX(Clients!$C$2:$C$501,$K$1)&"")&" "&IF($K$1=0,"",INDEX(Clients!$D$2:$D$501,$K$1)&""))) -> À l'attention de M. Pierre DURAND
D12: =IF($K$1=0,"",INDEX(Clients!$F$2:$F$501,$K$1)&"") -> 5 avenue des Tilleuls
D13: =IF(IF($K$1=0,"",INDEX(Clients!$G$2:$G$501,$K$1)&"")="",TRIM(IF($K$1=0,"",INDEX(Clients!$H$2:$H$501,$K$1)&"")&" "&UPPER(IF($K$1=0,"",INDEX(Clients!$I$2:$I$501,$K$1)&""))),IF($K$1=0,"",INDEX(Clients!$G$2:$G$501,$K$1)&"")) -> 69100 VILLEURBANNE
D14: =IF(IF($K$1=0,"",INDEX(Clients!$G$2:$G$501,$K$1)&"")="","",TRIM(IF($K$1=0,"",INDEX(Clients!$H$2:$H$501,$K$1)&"")&" "&UPPER(IF($K$1=0,"",INDEX(Clients!$I$2:$I$501,$K$1)&""))))
D16: =Cab_Ville&", le "&DAY(Date_Courrier)&IF(DAY(Date_Courrier)=1,"er","")&" "&INDEX(Liste_Mois,MONTH(Date_Courrier))&" "&YEAR(Date_Courrier) -> Le Plessis-Bouchard, le 22 septembre 2026
B18: =SUBSTITUTE(SUBSTITUTE(SUBSTITUTE(SUBSTITUTE(SUBSTITUTE(Txt_Objet,"{cabinet}",Cab_Nom),"{societe}",IF($K$1=0,"",INDEX(Clients!$E$2:$E$501,$K$1)&"")),"{date_effet}",$K$3),"{hausse}",$K$4),"{civilite}",$K$2) -> Objet : révision de nos honoraires au 1er janvier 2027
B20: =$K$2&"," -> Monsieur,
B22: =SUBSTITUTE(SUBSTITUTE(SUBSTITUTE(SUBSTITUTE(SUBSTITUTE(Txt_P1,"{cabinet}",Cab_Nom),"{societe}",IF($K$1=0,"",INDEX(Clients!$E$2:$E$501,$K$1)&"")),"{date_effet}",$K$3),"{hausse}",$K$4),"{civilite}",$K$2) -> Nous tenons tout d'abord à vous remercier pour la confiance que vous accordez à ALTHO EXPERTISE. Comme chaque année, et conformément aux dispositions de votre lettre de mission, nous procédons à la révision de nos honoraires.
B23: =SUBSTITUTE(SUBSTITUTE(SUBSTITUTE(SUBSTITUTE(SUBSTITUTE(Txt_P2,"{cabinet}",Cab_Nom),"{societe}",IF($K$1=0,"",INDEX(Clients!$E$2:$E$501,$K$1)&"")),"{date_effet}",$K$3),"{hausse}",$K$4),"{civilite}",$K$2) -> Cette révision, que nous avons souhaitée mesurée, tient compte de l'évolution de nos charges (rémunération et formation continue de nos collaborateurs, logiciels, sécurité informatique) ainsi que du renforcement constant des obligations comptables, fiscales, sociales et juridiques qui s'imposent à votre entreprise.
B24: =SUBSTITUTE(SUBSTITUTE(SUBSTITUTE(SUBSTITUTE(SUBSTITUTE(Txt_P3,"{cabinet}",Cab_Nom),"{societe}",IF($K$1=0,"",INDEX(Clients!$E$2:$E$501,$K$1)&"")),"{date_effet}",$K$3),"{hausse}",$K$4),"{civilite}",$K$2) -> L'année à venir est également marquée par la généralisation de la facturation électronique : depuis le 1er septembre 2026, toutes les entreprises doivent être en mesure de recevoir leurs factures électroniques via une plateforme agréée, et l'obligation d'émission s'étendra aux PME et micro-entreprises au 1er septembre 2027. Notre cabinet vous accompagne dans cette transition grâce à une solution de plateforme agréée directement intégrée à votre dossier.
B25: =SUBSTITUTE(SUBSTITUTE(SUBSTITUTE(SUBSTITUTE(SUBSTITUTE(Txt_P4,"{cabinet}",Cab_Nom),"{societe}",IF($K$1=0,"",INDEX(Clients!$E$2:$E$501,$K$1)&"")),"{date_effet}",$K$3),"{hausse}",$K$4),"{civilite}",$K$2) -> À compter du 1er janvier 2027, vos honoraires annuels hors taxes évolueront ainsi (évolution globale : 3.5 %) :
B27: Mission | C27: Actuel HT | D27: Évol. | E27: Nouveau HT | F27: Écart HT | J27: Libellé | K27: Actuel | L27: Nouveau | M27: Actif | N27: Rang | O27: k
B28: =IFERROR(INDEX($J$28:$J$31,MATCH($O28,$N$28:$N$31,0)),"") -> Mission comptable (tenue, révision, bilan, liasse fiscale) | C28: =IFERROR(INDEX($K$28:$K$31,MATCH($O28,$N$28:$N$31,0)),"") -> 3600 | D28: =IF(OR(E28="",N(C28)=0),"",E28/C28-1) -> 0.035 | E28: =IFERROR(INDEX($L$28:$L$31,MATCH($O28,$N$28:$N$31,0)),"") -> 3726 | F28: =IF(E28="","",E28-C28) -> 126 | J28: =Lib_Compta -> Mission comptable (tenue, révision, bilan, liasse fiscale) | K28: =IF($K$1=0,0,N(INDEX(Clients!$K$2:$K$501,$K$1))) -> 3600 | L28: =IF($K$1=0,0,N(INDEX(Clients!$P$2:$P$501,$K$1))) -> 3726 | M28: =IF(OR(K28<>0,L28<>0),1,0) -> 1 | N28: =IF(M28=1,SUM($M$28:M28),"") -> 1 | O28: 1
B29: =IFERROR(INDEX($J$28:$J$31,MATCH($O29,$N$28:$N$31,0)),"") -> Mission sociale (bulletins de paie, DSN, déclarations sociales) | C29: =IFERROR(INDEX($K$28:$K$31,MATCH($O29,$N$28:$N$31,0)),"") -> 1800 | D29: =IF(OR(E29="",N(C29)=0),"",E29/C29-1) -> 0.04 | E29: =IFERROR(INDEX($L$28:$L$31,MATCH($O29,$N$28:$N$31,0)),"") -> 1872 | F29: =IF(E29="","",E29-C29) -> 72 | J29: =Lib_Paye -> Mission sociale (bulletins de paie, DSN, déclarations sociales) | K29: =IF($K$1=0,0,N(INDEX(Clients!$L$2:$L$501,$K$1))) -> 1800 | L29: =IF($K$1=0,0,N(INDEX(Clients!$Q$2:$Q$501,$K$1))) -> 1872 | M29: =IF(OR(K29<>0,L29<>0),1,0) -> 1 | N29: =IF(M29=1,SUM($M$28:M29),"") -> 2 | O29: 2
B30: =IFERROR(INDEX($J$28:$J$31,MATCH($O30,$N$28:$N$31,0)),"") -> Mission juridique (approbation des comptes, secrétariat juridique) | C30: =IFERROR(INDEX($K$28:$K$31,MATCH($O30,$N$28:$N$31,0)),"") -> 600 | D30: =IF(OR(E30="",N(C30)=0),"",E30/C30-1) -> 0.03 | E30: =IFERROR(INDEX($L$28:$L$31,MATCH($O30,$N$28:$N$31,0)),"") -> 618 | F30: =IF(E30="","",E30-C30) -> 18 | J30: =Lib_Jur -> Mission juridique (approbation des comptes, secrétariat juridique) | K30: =IF($K$1=0,0,N(INDEX(Clients!$M$2:$M$501,$K$1))) -> 600 | L30: =IF($K$1=0,0,N(INDEX(Clients!$R$2:$R$501,$K$1))) -> 618 | M30: =IF(OR(K30<>0,L30<>0),1,0) -> 1 | N30: =IF(M30=1,SUM($M$28:M30),"") -> 3 | O30: 3
B31: =IFERROR(INDEX($J$28:$J$31,MATCH($O31,$N$28:$N$31,0)),"") -> Plateforme agréée – facturation électronique | C31: =IFERROR(INDEX($K$28:$K$31,MATCH($O31,$N$28:$N$31,0)),"") -> 240 | D31: =IF(OR(E31="",N(C31)=0),"",E31/C31-1) -> 0 | E31: =IFERROR(INDEX($L$28:$L$31,MATCH($O31,$N$28:$N$31,0)),"") -> 240 | F31: =IF(E31="","",E31-C31) -> 0 | J31: =Lib_PA -> Plateforme agréée – facturation électronique | K31: =IF($K$1=0,0,N(INDEX(Clients!$N$2:$N$501,$K$1))) -> 240 | L31: =IF($K$1=0,0,N(INDEX(Clients!$S$2:$S$501,$K$1))) -> 240 | M31: =IF(OR(K31<>0,L31<>0),1,0) -> 1 | N31: =IF(M31=1,SUM($M$28:M31),"") -> 4 | O31: 4
B32: Total annuel HT | C32: =SUM(K28:K31) -> 6240 | D32: =IF(N(C32)=0,"",E32/C32-1) -> 0.034615385 | E32: =SUM(L28:L31) -> 6456 | F32: =E32-C32 -> 216
B33: =IF(N(Nb_Mensualites)=0,"","Soit "&FIXED(E32/Nb_Mensualites,2)&" € HT par échéance ("&Nb_Mensualites&" échéances), "&FIXED(E32/Nb_Mensualites*(1+Taux_TVA),2)&" € TTC.") -> Soit 538.00 € HT par échéance (12 échéances), 645.60 € TTC.
B35: =SUBSTITUTE(SUBSTITUTE(SUBSTITUTE(SUBSTITUTE(SUBSTITUTE(Txt_P5,"{cabinet}",Cab_Nom),"{societe}",IF($K$1=0,"",INDEX(Clients!$E$2:$E$501,$K$1)&"")),"{date_effet}",$K$3),"{hausse}",$K$4),"{civilite}",$K$2) -> Les autres conditions de votre lettre de mission demeurent inchangées. Les nouveaux montants seront appliqués automatiquement sur vos prochaines factures et échéances de prélèvement.
B36: =SUBSTITUTE(SUBSTITUTE(SUBSTITUTE(SUBSTITUTE(SUBSTITUTE(Txt_P6,"{cabinet}",Cab_Nom),"{societe}",IF($K$1=0,"",INDEX(Clients!$E$2:$E$501,$K$1)&"")),"{date_effet}",$K$3),"{hausse}",$K$4),"{civilite}",$K$2) -> Votre interlocuteur habituel reste à votre entière disposition pour répondre à vos questions et faire le point sur l'évolution de vos besoins.
B37: =SUBSTITUTE(SUBSTITUTE(SUBSTITUTE(SUBSTITUTE(SUBSTITUTE(Txt_Politesse,"{cabinet}",Cab_Nom),"{societe}",IF($K$1=0,"",INDEX(Clients!$E$2:$E$501,$K$1)&"")),"{date_effet}",$K$3),"{hausse}",$K$4),"{civilite}",$K$2) -> Nous vous prions d'agréer, Monsieur, l'expression de nos salutations distinguées.
D39: =Signataire -> Prénom NOM
D40: =Signataire_Titre -> Expert-comptable associé
B45: =Cab_Mentions -> ALTHO EXPERTISE · SAS au capital de 10 000 € · RCS Pontoise 919 706 325 · TVA FR62919706325 · Société d'expertise comptable inscrite au Tableau de l'Ordre des experts-comptables de Paris Île-de-France

Sheet Impression en masse
J1: Ligne client | K1: =IFERROR(MATCH(1,Clients!$Z$2:$Z$501,0),0) -> 1
B2: =Cab_Nom -> ALTHO EXPERTISE | E2: =IF($K$1=0,"","Réf. client : "&INDEX(Clients!$A$2:$A$501,$K$1)) -> Réf. client : C001 | I2: COURRIERS À IMPRIMER | J2: Civilité longue | K2: =IF(IF($K$1=0,"",INDEX(Clients!$B$2:$B$501,$K$1)&"")="Mme","Madame",IF(IF($K$1=0,"",INDEX(Clients!$B$2:$B$501,$K$1)&"")="M.","Monsieur","Madame, Monsieur")) -> Monsieur
B3: =Cab_Adr1 -> 141 rue Charles de Gaulle | I3: =Nb_Courriers -> 2 | J3: Date effet texte | K3: =DAY(Date_Effet)&IF(DAY(Date_Effet)=1,"er","")&" "&INDEX(Liste_Mois,MONTH(Date_Effet))&" "&YEAR(Date_Effet) -> 1er janvier 2027
B4: =Cab_CPVille -> 95130 LE PLESSIS-BOUCHARD | J4: Hausse globale | K4: =IF(SUM($K$28:$K$31)=0,"",FIXED((SUM($L$28:$L$31)/SUM($K$28:$K$31)-1)*100,1)&" %") -> 3.5 %
B5: =Cab_Contact -> Tél. 01 34 14 53 45 · altho@altho-experts.com · altho-experts.com | I5: Fichier > Imprimer : tous les courriers sortent d'un coup (1 page par client). Fichier > Exporter > PDF : un seul PDF avec tous les courriers. Si des pages vierges apparaissent, imprimez les pages 1 à N (N = nombre ci-dessus). Sélection des clients : colonnes « À envoyer » et « Mode d'envoi » de l'onglet Clients.
D10: =IF($K$1=0,"",INDEX(Clients!$E$2:$E$501,$K$1)&"") -> SARL DURAND BÂTIMENT
D11: =IF(IF($K$1=0,"",INDEX(Clients!$D$2:$D$501,$K$1)&"")="","","À l'attention de "&TRIM(IF($K$1=0,"",INDEX(Clients!$B$2:$B$501,$K$1)&"")&" "&IF($K$1=0,"",INDEX(Clients!$C$2:$C$501,$K$1)&"")&" "&IF($K$1=0,"",INDEX(Clients!$D$2:$D$501,$K$1)&""))) -> À l'attention de M. Pierre DURAND
D12: =IF($K$1=0,"",INDEX(Clients!$F$2:$F$501,$K$1)&"") -> 5 avenue des Tilleuls
D13: =IF(IF($K$1=0,"",INDEX(Clients!$G$2:$G$501,$K$1)&"")="",TRIM(IF($K$1=0,"",INDEX(Clients!$H$2:$H$501,$K$1)&"")&" "&UPPER(IF($K$1=0,"",INDEX(Clients!$I$2:$I$501,$K$1)&""))),IF($K$1=0,"",INDEX(Clients!$G$2:$G$501,$K$1)&"")) -> 69100 VILLEURBANNE
D14: =IF(IF($K$1=0,"",INDEX(Clients!$G$2:$G$501,$K$1)&"")="","",TRIM(IF($K$1=0,"",INDEX(Clients!$H$2:$H$501,$K$1)&"")&" "&UPPER(IF($K$1=0,"",INDEX(Clients!$I$2:$I$501,$K$1)&""))))
D16: =Cab_Ville&", le "&DAY(Date_Courrier)&IF(DAY(Date_Courrier)=1,"er","")&" "&INDEX(Liste_Mois,MONTH(Date_Courrier))&" "&YEAR(Date_Courrier) -> Le Plessis-Bouchard, le 22 septembre 2026
B18: =SUBSTITUTE(SUBSTITUTE(SUBSTITUTE(SUBSTITUTE(SUBSTITUTE(Txt_Objet,"{cabinet}",Cab_Nom),"{societe}",IF($K$1=0,"",INDEX(Clients!$E$2:$E$501,$K$1)&"")),"{date_effet}",$K$3),"{hausse}",$K$4),"{civilite}",$K$2) -> Objet : révision de nos honoraires au 1er janvier 2027
B20: =$K$2&"," -> Monsieur,
B22: =SUBSTITUTE(SUBSTITUTE(SUBSTITUTE(SUBSTITUTE(SUBSTITUTE(Txt_P1,"{cabinet}",Cab_Nom),"{societe}",IF($K$1=0,"",INDEX(Clients!$E$2:$E$501,$K$1)&"")),"{date_effet}",$K$3),"{hausse}",$K$4),"{civilite}",$K$2) -> Nous tenons tout d'abord à vous remercier pour la confiance que vous accordez à ALTHO EXPERTISE. Comme chaque année, et conformément aux dispositions de votre lettre de mission, nous procédons à la révision de nos honoraires.
B23: =SUBSTITUTE(SUBSTITUTE(SUBSTITUTE(SUBSTITUTE(SUBSTITUTE(Txt_P2,"{cabinet}",Cab_Nom),"{societe}",IF($K$1=0,"",INDEX(Clients!$E$2:$E$501,$K$1)&"")),"{date_effet}",$K$3),"{hausse}",$K$4),"{civilite}",$K$2) -> Cette révision, que nous avons souhaitée mesurée, tient compte de l'évolution de nos charges (rémunération et formation continue de nos collaborateurs, logiciels, sécurité informatique) ainsi que du renforcement constant des obligations comptables, fiscales, sociales et juridiques qui s'imposent à votre entreprise.
B24: =SUBSTITUTE(SUBSTITUTE(SUBSTITUTE(SUBSTITUTE(SUBSTITUTE(Txt_P3,"{cabinet}",Cab_Nom),"{societe}",IF($K$1=0,"",INDEX(Clients!$E$2:$E$501,$K$1)&"")),"{date_effet}",$K$3),"{hausse}",$K$4),"{civilite}",$K$2) -> L'année à venir est également marquée par la généralisation de la facturation électronique : depuis le 1er septembre 2026, toutes les entreprises doivent être en mesure de recevoir leurs factures électroniques via une plateforme agréée, et l'obligation d'émission s'étendra aux PME et micro-entreprises au 1er septembre 2027. Notre cabinet vous accompagne dans cette transition grâce à une solution de plateforme agréée directement intégrée à votre dossier.
B25: =SUBSTITUTE(SUBSTITUTE(SUBSTITUTE(SUBSTITUTE(SUBSTITUTE(Txt_P4,"{cabinet}",Cab_Nom),"{societe}",IF($K$1=0,"",INDEX(Clients!$E$2:$E$501,$K$1)&"")),"{date_effet}",$K$3),"{hausse}",$K$4),"{civilite}",$K$2) -> À compter du 1er janvier 2027, vos honoraires annuels hors taxes évolueront ainsi (évolution globale : 3.5 %) :
B27: Mission | C27: Actuel HT | D27: Évol. | E27: Nouveau HT | F27: Écart HT | J27: Libellé | K27: Actuel | L27: Nouveau | M27: Actif | N27: Rang | O27: k
B28: =IFERROR(INDEX($J$28:$J$31,MATCH($O28,$N$28:$N$31,0)),"") -> Mission comptable (tenue, révision, bilan, liasse fiscale) | C28: =IFERROR(INDEX($K$28:$K$31,MATCH($O28,$N$28:$N$31,0)),"") -> 3600 | D28: =IF(OR(E28="",N(C28)=0),"",E28/C28-1) -> 0.035 | E28: =IFERROR(INDEX($L$28:$L$31,MATCH($O28,$N$28:$N$31,0)),"") -> 3726 | F28: =IF(E28="","",E28-C28) -> 126 | J28: =Lib_Compta -> Mission comptable (tenue, révision, bilan, liasse fiscale) | K28: =IF($K$1=0,0,N(INDEX(Clients!$K$2:$K$501,$K$1))) -> 3600 | L28: =IF($K$1=0,0,N(INDEX(Clients!$P$2:$P$501,$K$1))) -> 3726 | M28: =IF(OR(K28<>0,L28<>0),1,0) -> 1 | N28: =IF(M28=1,SUM($M$28:M28),"") -> 1 | O28: 1
B29: =IFERROR(INDEX($J$28:$J$31,MATCH($O29,$N$28:$N$31,0)),"") -> Mission sociale (bulletins de paie, DSN, déclarations sociales) | C29: =IFERROR(INDEX($K$28:$K$31,MATCH($O29,$N$28:$N$31,0)),"") -> 1800 | D29: =IF(OR(E29="",N(C29)=0),"",E29/C29-1) -> 0.04 | E29: =IFERROR(INDEX($L$28:$L$31,MATCH($O29,$N$28:$N$31,0)),"") -> 1872 | F29: =IF(E29="","",E29-C29) -> 72 | J29: =Lib_Paye -> Mission sociale (bulletins de paie, DSN, déclarations sociales) | K29: =IF($K$1=0,0,N(INDEX(Clients!$L$2:$L$501,$K$1))) -> 1800 | L29: =IF($K$1=0,0,N(INDEX(Clients!$Q$2:$Q$501,$K$1))) -> 1872 | M29: =IF(OR(K29<>0,L29<>0),1,0) -> 1 | N29: =IF(M29=1,SUM($M$28:M29),"") -> 2 | O29: 2
B30: =IFERROR(INDEX($J$28:$J$31,MATCH($O30,$N$28:$N$31,0)),"") -> Mission juridique (approbation des comptes, secrétariat juridique) | C30: =IFERROR(INDEX($K$28:$K$31,MATCH($O30,$N$28:$N$31,0)),"") -> 600 | D30: =IF(OR(E30="",N(C30)=0),"",E30/C30-1) -> 0.03 | E30: =IFERROR(INDEX($L$28:$L$31,MATCH($O30,$N$28:$N$31,0)),"") -> 618 | F30: =IF(E30="","",E30-C30) -> 18 | J30: =Lib_Jur -> Mission juridique (approbation des comptes, secrétariat juridique) | K30: =IF($K$1=0,0,N(INDEX(Clients!$M$2:$M$501,$K$1))) -> 600 | L30: =IF($K$1=0,0,N(INDEX(Clients!$R$2:$R$501,$K$1))) -> 618 | M30: =IF(OR(K30<>0,L30<>0),1,0) -> 1 | N30: =IF(M30=1,SUM($M$28:M30),"") -> 3 | O30: 3
B31: =IFERROR(INDEX($J$28:$J$31,MATCH($O31,$N$28:$N$31,0)),"") -> Plateforme agréée – facturation électronique | C31: =IFERROR(INDEX($K$28:$K$31,MATCH($O31,$N$28:$N$31,0)),"") -> 240 | D31: =IF(OR(E31="",N(C31)=0),"",E31/C31-1) -> 0 | E31: =IFERROR(INDEX($L$28:$L$31,MATCH($O31,$N$28:$N$31,0)),"") -> 240 | F31: =IF(E31="","",E31-C31) -> 0 | J31: =Lib_PA -> Plateforme agréée – facturation électronique | K31: =IF($K$1=0,0,N(INDEX(Clients!$N$2:$N$501,$K$1))) -> 240 | L31: =IF($K$1=0,0,N(INDEX(Clients!$S$2:$S$501,$K$1))) -> 240 | M31: =IF(OR(K31<>0,L31<>0),1,0) -> 1 | N31: =IF(M31=1,SUM($M$28:M31),"") -> 4 | O31: 4
B32: Total annuel HT | C32: =SUM(K28:K31) -> 6240 | D32: =IF(N(C32)=0,"",E32/C32-1) -> 0.034615385 | E32: =SUM(L28:L31) -> 6456 | F32: =E32-C32 -> 216
B33: =IF(N(Nb_Mensualites)=0,"","Soit "&FIXED(E32/Nb_Mensualites,2)&" € HT par échéance ("&Nb_Mensualites&" échéances), "&FIXED(E32/Nb_Mensualites*(1+Taux_TVA),2)&" € TTC.") -> Soit 538.00 € HT par échéance (12 échéances), 645.60 € TTC.
B35: =SUBSTITUTE(SUBSTITUTE(SUBSTITUTE(SUBSTITUTE(SUBSTITUTE(Txt_P5,"{cabinet}",Cab_Nom),"{societe}",IF($K$1=0,"",INDEX(Clients!$E$2:$E$501,$K$1)&"")),"{date_effet}",$K$3),"{hausse}",$K$4),"{civilite}",$K$2) -> Les autres conditions de votre lettre de mission demeurent inchangées. Les nouveaux montants seront appliqués automatiquement sur vos prochaines factures et échéances de prélèvement.
B36: =SUBSTITUTE(SUBSTITUTE(SUBSTITUTE(SUBSTITUTE(SUBSTITUTE(Txt_P6,"{cabinet}",Cab_Nom),"{societe}",IF($K$1=0,"",INDEX(Clients!$E$2:$E$501,$K$1)&"")),"{date_effet}",$K$3),"{hausse}",$K$4),"{civilite}",$K$2) -> Votre interlocuteur habituel reste à votre entière disposition pour répondre à vos questions et faire le point sur l'évolution de vos besoins.
B37: =SUBSTITUTE(SUBSTITUTE(SUBSTITUTE(SUBSTITUTE(SUBSTITUTE(Txt_Politesse,"{cabinet}",Cab_Nom),"{societe}",IF($K$1=0,"",INDEX(Clients!$E$2:$E$501,$K$1)&"")),"{date_effet}",$K$3),"{hausse}",$K$4),"{civilite}",$K$2) -> Nous vous prions d'agréer, Monsieur, l'expression de nos salutations distinguées.
D39: =Signataire -> Prénom NOM
D40: =Signataire_Titre -> Expert-comptable associé
B45: =Cab_Mentions -> ALTHO EXPERTISE · SAS au capital de 10 000 € · RCS Pontoise 919 706 325 · TVA FR62919706325 · Société d'expertise comptable inscrite au Tableau de l'Ordre des experts-comptables de Paris Île-de-France
J46: Ligne client | K46: =IFERROR(MATCH(2,Clients!$Z$2:$Z$501,0),0) -> 3
B47: =Cab_Nom -> ALTHO EXPERTISE | E47: =IF($K$46=0,"","Réf. client : "&INDEX(Clients!$A$2:$A$501,$K$46)) -> Réf. client : C003 | J47: Civilité longue | K47: =IF(IF($K$46=0,"",INDEX(Clients!$B$2:$B$501,$K$46)&"")="Mme","Madame",IF(IF($K$46=0,"",INDEX(Clients!$B$2:$B$501,$K$46)&"")="M.","Monsieur","Madame, Monsieur")) -> Madame, Monsieur
B48: =Cab_Adr1 -> 141 rue Charles de Gaulle | J48: Date effet texte | K48: =DAY(Date_Effet)&IF(DAY(Date_Effet)=1,"er","")&" "&INDEX(Liste_Mois,MONTH(Date_Effet))&" "&YEAR(Date_Effet) -> 1er janvier 2027
B49: =Cab_CPVille -> 95130 LE PLESSIS-BOUCHARD | J49: Hausse globale | K49: =IF(SUM($K$73:$K$76)=0,"",FIXED((SUM($L$73:$L$76)/SUM($K$73:$K$76)-1)*100,1)&" %") -> 3.5 %
B50: =Cab_Contact -> Tél. 01 34 14 53 45 · altho@altho-experts.com · altho-experts.com
D55: =IF($K$46=0,"",INDEX(Clients!$E$2:$E$501,$K$46)&"") -> EURL LES JARDINS DE CLAIRE
D56: =IF(IF($K$46=0,"",INDEX(Clients!$D$2:$D$501,$K$46)&"")="","","À l'attention de "&TRIM(IF($K$46=0,"",INDEX(Clients!$B$2:$B$501,$K$46)&"")&" "&IF($K$46=0,"",INDEX(Clients!$C$2:$C$501,$K$46)&"")&" "&IF($K$46=0,"",INDEX(Clients!$D$2:$D$501,$K$46)&"")))
D57: =IF($K$46=0,"",INDEX(Clients!$F$2:$F$501,$K$46)&"") -> 18 chemin des Vignes
D58: =IF(IF($K$46=0,"",INDEX(Clients!$G$2:$G$501,$K$46)&"")="",TRIM(IF($K$46=0,"",INDEX(Clients!$H$2:$H$501,$K$46)&"")&" "&UPPER(IF($K$46=0,"",INDEX(Clients!$I$2:$I$501,$K$46)&""))),IF($K$46=0,"",INDEX(Clients!$G$2:$G$501,$K$46)&"")) -> 69400 VILLEFRANCHE-SUR-SAÔNE
D59: =IF(IF($K$46=0,"",INDEX(Clients!$G$2:$G$501,$K$46)&"")="","",TRIM(IF($K$46=0,"",INDEX(Clients!$H$2:$H$501,$K$46)&"")&" "&UPPER(IF($K$46=0,"",INDEX(Clients!$I$2:$I$501,$K$46)&""))))
...

Sheet Macro PDF
A1: Code VBA à coller dans un module (Alt + F11 > Insertion > Module), fichier enregistré en .xlsm
A3: '=====================================================================
A4: ' Publipostage - Courrier d'augmentation tarifaire
A5: ' Onglets requis : "Clients" (en-tetes ligne 1) et "Courrier"
A6: ' Nom defini requis : Client_Selectionne (cellule Courrier!I3)
A7: '=====================================================================
A8: Option Explicit
A10: Private Const COL_CODE As String = "A"
A11: Private Const COL_SOCIETE As String = "E"
A12: Private Const COL_ENVOI As String = "X"
A13: Private Const COL_MODE As String = "Y"
A15: ' Un PDF par client (A envoyer = Oui) dans le sous-dossier Courriers_PDF
... A147: End Function
